<?xml version="1.0" ?>
<robot name="PRRRRR_Robot">

<!-- ********** Inertial Properties and Geometry (Links) ********** -->
	<link name="world" />
	<link name="s_frame" />
	<link name="link1" />
	<link name="link2" />
	<link name="link3" />
	<link name="link4" />
	<link name="link5" />
	<link name="link6" />
	<link name="b_frame" />
	
	
<!-- ********** Kinematic Properties (Joints) ********** -->
	<joint name="s_frame" type="fixed">
		<parent link="world"/>
		<child link="s_frame"/>
		<origin rpy="0.0 0.0 0.0" xyz="0.0 0.0 0.0"/>
	</joint>
	
	<joint name="joint1" type="prismatic"> <!-- For a prismatic joint use "prismatic" instead of "continuous" -->
		<parent link="s_frame"/>
		<child link="link1"/>
		<origin rpy="0.0 0.0 0.0" xyz="0.0 0.2 0.0"/> <!-- l1 = 0.2 m -->
		<limit effort="1000.0" lower="-0.38" upper="0" velocity="1"/>
		<axis xyz="0 1 0"/>
	</joint>

	<joint name="joint2" type="continuous"> <!-- For a prismatic joint use "prismatic" instead of "continuous" -->
		<parent link="link1"/>
		<child link="link2"/>
		<origin rpy="0.0 0.0 0.0" xyz="0.0 0.0 0.0"/>
		<axis xyz="0 0 1"/>
	</joint>
	
	<joint name="joint3" type="continuous">
		<parent link="link2"/>
		<child link="link3"/>
		<origin rpy="0.0 0.0 0.0" xyz="0.0 0.0 0.35"/> <!-- h = 0.35 m -->
		<axis xyz="1 0 0"/>
	</joint>
	
	<joint name="joint4" type="continuous">
		<parent link="link3"/>
		<child link="link4"/>
		<origin rpy="0.0 0.0 0.0" xyz="0.0 0.20 0.0"/> <!-- l2 = 0.20 m -->
		<axis xyz="1 0 0"/>
	</joint>

	<joint name="joint5" type="continuous">
		<parent link="link4"/>
		<child link="link5"/>
		<origin rpy="0.0 0.0 0.0" xyz="0.0 0.20 0.0"/> <!-- l3 = 0.20 m -->
		<axis xyz="1 0 0"/>
	</joint>

	<joint name="joint6" type="continuous">
		<parent link="link5"/>
		<child link="link6"/>
		<origin rpy="0.0 0.0 0.0" xyz="0.0 0.20 0.0"/> <!-- l4 = 0.20 m -->
		<axis xyz="0 1 0"/>
	</joint>
	
	<joint name="b_frame" type="fixed">
		<origin rpy="0 0 0" xyz="0.0 0.10 0.0"/> <!-- l5 = 0.10 m -->
		<parent link="link6"/>
		<child link="b_frame"/>
	</joint>
	
</robot>